Workbook

Sheet Resumen
A1: Resumen de cumplimiento — Sistema de Gestión y Trazabilidad de Incidencias (Mallplaza Copiapó)
A2: Estado al 10 de octubre de 2026, según el repositorio y la suite de 33 pruebas. Los totales se calculan con fórmulas a partir de las hojas 'Matriz RF' y 'Matriz RNF'.
A4: Estado | B4: RF (cantidad) | C4: RF (%) | D4: RNF (cantidad) | E4: RNF (%) | G4: Casos de prueba | H4: Cantidad
A5: Implementado y probado | B5: =COUNTIF('Matriz RF'!$H$5:$H$44,A5) -> 29 | C5: =B5/$B$11 -> 0.725 | D5: =COUNTIF('Matriz RNF'!$F$5:$F$18,A5) -> 3 | E5: =D5/$D$11 -> 0.21428571 | G5: Aprobado | H5: =COUNTIF('Casos de prueba'!$L$5:$L$68,G5) -> 45
A6: Implementado | B6: =COUNTIF('Matriz RF'!$H$5:$H$44,A6) -> 2 | C6: =B6/$B$11 -> 0.05 | D6: =COUNTIF('Matriz RNF'!$F$5:$F$18,A6) -> 2 | E6: =D6/$D$11 -> 0.14285714 | G6: Observación | H6: =COUNTIF('Casos de prueba'!$L$5:$L$68,G6) -> 1
A7: Parcial | B7: =COUNTIF('Matriz RF'!$H$5:$H$44,A7) -> 5 | C7: =B7/$B$11 -> 0.125 | D7: =COUNTIF('Matriz RNF'!$F$5:$F$18,A7) -> 4 | E7: =D7/$D$11 -> 0.28571429 | G7: Por ejecutar | H7: =COUNTIF('Casos de prueba'!$L$5:$L$68,G7) -> 10
A8: Mock | B8: =COUNTIF('Matriz RF'!$H$5:$H$44,A8) -> 1 | C8: =B8/$B$11 -> 0.025 | D8: =COUNTIF('Matriz RNF'!$F$5:$F$18,A8) -> 0 | E8: =D8/$D$11 -> 0 | G8: Bloqueado (funcionalidad pendiente) | H8: =COUNTIF('Casos de prueba'!$L$5:$L$68,G8) -> 8
A9: Pendiente | B9: =COUNTIF('Matriz RF'!$H$5:$H$44,A9) -> 3 | C9: =B9/$B$11 -> 0.075 | D9: =COUNTIF('Matriz RNF'!$F$5:$F$18,A9) -> 3 | E9: =D9/$D$11 -> 0.21428571 | G9: Total | H9: =SUM(H5:H8) -> 64
A10: Diseñado (no desplegado) | B10: =COUNTIF('Matriz RF'!$H$5:$H$44,A10) -> 0 | C10: =B10/$B$11 -> 0 | D10: =COUNTIF('Matriz RNF'!$F$5:$F$18,A10) -> 2 | E10: =D10/$D$11 -> 0.14285714
A11: Total | B11: =SUM(B5:B10) -> 40 | C11: =SUM(C5:C10) -> 1 | D11: =SUM(D5:D10) -> 14 | E11: =SUM(E5:E10) -> 1
A13: RF con funcionalidad construida (Implementado y probado + Implementado) | B13: =B5+B6 -> 31 | C13: =B13/B11 -> 0.775
A14: RF con avance parcial, mock o pendientes | B14: =B7+B8+B9 -> 9 | C14: =B14/B11 -> 0.225
A16: RF por prioridad MoSCoW y estado (clasificación del Informe 1)
A17: MoSCoW | B17: Total | C17: Construidos | D17: Parciales o mock | E17: Pendientes
A18: Must have | B18: =COUNTIF('Matriz RF'!$D$5:$D$44,A18) -> 18 | C18: =COUNTIFS('Matriz RF'!$D$5:$D$44,A18,'Matriz RF'!$H$5:$H$44,"Implementado y probado")+COUNTIFS('Matriz RF'!$D$5:$D$44,A18,'Matriz RF'!$H$5:$H$44,"Implementado") -> 17 | D18: =COUNTIFS('Matriz RF'!$D$5:$D$44,A18,'Matriz RF'!$H$5:$H$44,"Parcial")+COUNTIFS('Matriz RF'!$D$5:$D$44,A18,'Matriz RF'!$H$5:$H$44,"Mock") -> 1 | E18: =COUNTIFS('Matriz RF'!$D$5:$D$44,A18,'Matriz RF'!$H$5:$H$44,"Pendiente") -> 0
A19: Should have | B19: =COUNTIF('Matriz RF'!$D$5:$D$44,A19) -> 13 | C19: =COUNTIFS('Matriz RF'!$D$5:$D$44,A19,'Matriz RF'!$H$5:$H$44,"Implementado y probado")+COUNTIFS('Matriz RF'!$D$5:$D$44,A19,'Matriz RF'!$H$5:$H$44,"Implementado") -> 10 | D19: =COUNTIFS('Matriz RF'!$D$5:$D$44,A19,'Matriz RF'!$H$5:$H$44,"Parcial")+COUNTIFS('Matriz RF'!$D$5:$D$44,A19,'Matriz RF'!$H$5:$H$44,"Mock") -> 2 | E19: =COUNTIFS('Matriz RF'!$D$5:$D$44,A19,'Matriz RF'!$H$5:$H$44,"Pendiente") -> 1
A20: Could have | B20: =COUNTIF('Matriz RF'!$D$5:$D$44,A20) -> 4 | C20: =COUNTIFS('Matriz RF'!$D$5:$D$44,A20,'Matriz RF'!$H$5:$H$44,"Implementado y probado")+COUNTIFS('Matriz RF'!$D$5:$D$44,A20,'Matriz RF'!$H$5:$H$44,"Implementado") -> 2 | D20: =COUNTIFS('Matriz RF'!$D$5:$D$44,A20,'Matriz RF'!$H$5:$H$44,"Parcial")+COUNTIFS('Matriz RF'!$D$5:$D$44,A20,'Matriz RF'!$H$5:$H$44,"Mock") -> 1 | E20: =COUNTIFS('Matriz RF'!$D$5:$D$44,A20,'Matriz RF'!$H$5:$H$44,"Pendiente") -> 1
A21: Sin clasificar | B21: =COUNTIF('Matriz RF'!$D$5:$D$44,A21) -> 5 | C21: =COUNTIFS('Matriz RF'!$D$5:$D$44,A21,'Matriz RF'!$H$5:$H$44,"Implementado y probado")+COUNTIFS('Matriz RF'!$D$5:$D$44,A21,'Matriz RF'!$H$5:$H$44,"Implementado") -> 2 | D21: =COUNTIFS('Matriz RF'!$D$5:$D$44,A21,'Matriz RF'!$H$5:$H$44,"Parcial")+COUNTIFS('Matriz RF'!$D$5:$D$44,A21,'Matriz RF'!$H$5:$H$44,"Mock") -> 2 | E21: =COUNTIFS('Matriz RF'!$D$5:$D$44,A21,'Matriz RF'!$H$5:$H$44,"Pendiente") -> 1
A23: Cómo leer los estados
A24: Implementado y probado: existe en el código y una prueba automatizada lo verifica.
A25: Implementado: existe en el código, sin prueba específica o con verificación pendiente de un detalle.
A26: Parcial: existe una parte (por ejemplo la base de datos o la interfaz) pero falta otra o falta validación externa.
A27: Mock: simulado; no se comunica con el sistema real. Pendiente: no existe.
A28: Diseñado (no desplegado): solo aplica a RNF de infraestructura; se verifica al desplegar.
A29: Un 'Implementado y probado' no significa aceptación del cliente: no ha habido UAT con Mallplaza.

Sheet Matriz RF
A1: Matriz de trazabilidad — Requerimientos funcionales (40 RF)
A2: Fuente de los RF: catálogo entregado por el equipo. Evidencia: repositorio lxishh/sistema-incidencias-mallplaza, rama feature/S1-demo-qr, con la suite de 33 pruebas verificada el 10-oct-2026. La columna MoSCoW proviene del Informe 1 (que tenía 35 RF); RF-36 a RF-40 aún no tienen clasificación.
A4: ID | B4: Módulo | C4: Requerimiento (resumen) | D4: MoSCoW | E4: Caso(s) de uso | F4: Componente o evidencia en el repositorio | G4: Prueba automatizada | H4: Estado | I4: Observación o brecha
A5: RF-01 | B5: Autenticación | C5: Inicio de sesión con correo y contraseña, exclusivo para Jefatura | D5: Must have | E5: CU-01 | F5: backend/src/routes/auth.js (POST /api/auth/login); tabla usuarios con rol JEFATURA | G5: integration.test.js › autenticación | H5: Implementado y probado
A6: RF-02 | B6: Autenticación | C6: Cola de incidencias y dashboard solo para Jefatura autenticada | D6: Must have | E6: CU-09, CU-13 | F6: backend/src/middleware/auth.js aplicado a GET /api/incidencias y /api/dashboard/kpis | G6: integration.test.js › autenticación (protege /me), dashboard KPI (protege el endpoint) | H6: Implementado y probado
A7: RF-03 | B7: Autenticación | C7: Cierre de sesión | D7: Must have | E7: CU-02 | F7: POST /api/auth/logout | G7: integration.test.js › autenticación (inicia y cierra sesión) | H7: Implementado y probado | I7: Pendiente revisar con herramientas del navegador un ERR_ABORTED observado en logout (tarea T6).
A8: RF-04 | B8: Reporte (QR) | C8: Acceso al formulario mediante QR abierto, sin login | D8: Must have | E8: CU-03 | F8: Ruta pública /#/report; backend/src/utils/qr.js y scripts/generate-demo-qr.js (QR de demostración con la URL de la app) | G8: qr.test.js (6 pruebas de formato del QR) | H8: Parcial | I8: El QR actual codifica la URL y la ruta es pública. Falta probar la lectura en iPhone y Android. Hay que resolver el conflicto con el documento arquitectónico (QR restringido al personal interno): ver hoja Discrepancias.
A9: RF-05 | B9: Reporte (QR) | C9: Seleccionar ubicación/zona desde una lista predefinida | D9: Must have | E9: CU-04 | F9: GET /api/catalogos; select en el formulario (frontend/src/main.js) | G9: integration.test.js › incidencias | H9: Implementado y probado | I9: El Informe 1 define 'Ubicación' como tres categorías de tránsito (Alto, Medio, Bajo), que el operario elige de una lista; eso es lo implementado. El catálogo habla de 'ubicación/zona': confirmar con el cliente si bastan las tres categorías o se necesitan zonas físicas (decisión D4).
A10: RF-06 | B10: Reporte (QR) | C10: RUT del operario como texto obligatorio (identificador de responsabilidad) | D10: Must have | E10: CU-04 | F10: Validación zod en routes/incidencias.js; columna rut_operario | G10: integration.test.js › incidencias; filters.test.js (RUT) | H10: Implementado y probado | I10: El RUT no se expone en la lista ni en los logs; sí en el detalle autenticado.
A11: RF-07 | B11: Reporte (QR) | C11: Seleccionar tipo de falla (Eléctrica, Sanitaria/Agua, Estructural, Estética/Confort, Mobiliario) | D11: Must have | E11: CU-04 | F11: Catálogo en GET /api/catalogos; enum en validación y esquema | G11: integration.test.js › incidencias; filters.test.js | H11: Implementado y probado
A12: RF-08 | B12: Reporte (QR) | C12: Indicar impacto operativo (Sí/No), obligatorio | D12: Must have | E12: CU-04 | F12: Validación zod; columna impacto_operativo | G12: rules.test.js; integration.test.js › incidencias | H12: Implementado y probado
A13: RF-09 | B13: Reporte (QR) | C13: Indicar riesgo de accidente (Sí/No), obligatorio | D13: Must have | E13: CU-04 | F13: Validación zod; columna riesgo_accidente | G13: rules.test.js; integration.test.js › incidencias | H13: Implementado y probado
A14: RF-10 | B14: Reporte (QR) | C14: Indicar si afecta a terceros (Sí/No), obligatorio | D14: Must have | E14: CU-04 | F14: Validación zod; columna afecta_terceros | G14: rules.test.js; integration.test.js › incidencias | H14: Implementado y probado
A15: RF-11 | B15: Reporte (QR) | C15: Comentario o descripción libre, opcional | D15: Could have | E15: CU-04 | F15: Campo comentario en formulario, validación y esquema | G15: Cubierto indirectamente en integration.test.js › incidencias | H15: Implementado | I15: Sin prueba específica del campo opcional.
A16: RF-12 | B16: Reporte (QR) | C16: Adjuntar de 1 a 3 fotografías (cámara o galería), de forma opcional | D16: Could have | E16: CU-05 | F16: Tabla evidencias_fotograficas en el esquema; sin endpoint ni interfaz de carga | G16: — | H16: Pendiente | I16: El requisito es ambiguo: es 'opcional' pero exige 'mínimo 1'. Interpretación propuesta: 0 fotos, o entre 1 y 3. Confirmar con el cliente. Faltan además política de retención y quién ve las fotos.
A17: RF-13 | B17: Reporte (QR) | C17: Validar que la evidencia tenga entre 1 y 3 fotografías antes de enviar | D17: Could have | E17: CU-05 | F17: Solo restricción en el esquema de base de datos | G17: — | H17: Parcial | I17: Falta la validación en API y en la interfaz.
A18: RF-14 | B18: Reporte (QR) | C18: Validar que los campos obligatorios estén completos antes de enviar | D18: Must have | E18: CU-04 | F18: Validación zod en el servidor; atributo required en el formulario | G18: integration.test.js › incidencias; filters.test.js | H18: Implementado y probado
A19: RF-15 | B19: Reporte (QR) | C19: Registrar fecha y hora de creación automáticamente | D19: Must have | E19: CU-04 | F19: Columna fecha_creacion con valor por defecto en la base | G19: integration.test.js › incidencias (borde de fecha en America/Santiago) | H19: Implementado y probado
A20: RF-16 | B20: Motor de reglas | C20: Asignar prioridad (Crítica, Alta, Media, Baja) con árbol de decisión determinista | D20: Must have | E20: CU-06 | F20: backend/src/rules/prioridad.js | G20: rules.test.js (24 combinaciones) | H20: Implementado y probado
A21: RF-17 | B21: Motor de reglas | C21: Aplicar las reglas en orden de severidad, deteniéndose en la primera que se cumpla | D21: Must have | E21: CU-06 | F21: backend/src/rules/prioridad.js (orden de las condiciones) | G21: rules.test.js (precedencia) | H21: Implementado y probado
A22: RF-18 | B22: Motor de reglas | C22: Almacenar la prioridad junto con la incidencia | D22: Must have | E22: CU-06 | F22: INSERT en routes/incidencias.js; columna prioridad | G22: integration.test.js › incidencias | H22: Implementado y probado
A23: RF-19 | B23: Gestión | C23: Jefatura cambia el estado (Pendiente → En proceso → Resuelta) | D23: Must have | E23: CU-12 | F23: PATCH /api/incidencias/:id/estado | G23: integration.test.js › incidencias (avanza con historial) | H23: Implementado y probado
A24: RF-20 | B24: Gestión | C24: Registrar fecha y hora de cierre al marcar Resuelta | D24: Must have | E24: CU-12 | F24: Columna fecha_cierre y restricciones del esquema | G24: integration.test.js › incidencias | H24: Implementado y probado
A25: RF-21 | B25: Gestión | C25: Impedir Resuelta si no pasó por En proceso | D25: Should have | E25: CU-12 | F25: Restricciones de estado en db/schema.sql y respuesta 409 de la API | G25: integration.test.js › incidencias; migration.test.js | H25: Implementado y probado
A26: RF-22 | B26: Gestión | C26: Consultar el historial completo de una incidencia | D26: Should have | E26: CU-11 | F26: GET /api/incidencias/:id (historial_estados ordenado por fecha) | G26: integration.test.js › incidencias | H26: Implementado y probado
A27: RF-23 | B27: Gestión | C27: Filtrar por estado | D27: Should have | E27: CU-10 | F27: GET /api/incidencias?estado=; barra de filtros | G27: filters.test.js; integration.test.js › incidencias | H27: Implementado y probado
A28: RF-24 | B28: Gestión | C28: Filtrar por prioridad | D28: Should have | E28: CU-10 | F28: GET /api/incidencias?prioridad= | G28: filters.test.js; integration.test.js › incidencias | H28: Implementado y probado
A29: RF-25 | B29: Gestión | C29: Filtrar por ubicación | D29: Should have | E29: CU-10 | F29: GET /api/incidencias?ubicacion= | G29: filters.test.js; integration.test.js › incidencias | H29: Implementado y probado | I29: Hoy filtra por nivel de tránsito; cambiará si RF-05 pasa a zonas.
A30: RF-26 | B30: Gestión | C30: Filtrar por tipo de falla | D30: Should have | E30: CU-10 | F30: GET /api/incidencias?tipo_falla= | G30: filters.test.js; integration.test.js › incidencias | H30: Implementado y probado
A31: RF-27 | B31: Gestión | C31: Buscar una incidencia por su identificador | D31: Should have | E31: CU-10 | F31: GET /api/incidencias?q=<id>; campo 'Buscar por ID' | G31: filters.test.js | H31: Implementado y probado
A32: RF-28 | B32: Dashboard y KPI | C32: Calcular y mostrar el MTTR | D32: Must have | E32: CU-13 | F32: backend/src/routes/dashboard.js (GET /api/dashboard/kpis) | G32: integration.test.js › dashboard KPI | H32: Implementado y probado
A33: RF-29 | B33: Dashboard y KPI | C33: Cantidad de incidencias por prioridad | D33: Should have | E33: CU-13 | F33: dashboard.js (por_prioridad) | G33: integration.test.js › dashboard KPI | H33: Implementado y probado
A34: RF-30 | B34: Dashboard y KPI | C34: Cantidad de incidencias por tipo de falla | D34: Should have | E34: CU-13 | F34: dashboard.js (por_tipo_falla) | G34: integration.test.js › dashboard KPI | H34: Implementado y probado
A35: RF-31 | B35: Dashboard y KPI | C35: Cantidad de incidencias por ubicación | D35: Should have | E35: CU-13 | F35: dashboard.js (por_ubicacion) | G35: integration.test.js › dashboard KPI | H35: Implementado y probado
A36: RF-32 | B36: Dashboard y KPI | C36: Filtrar los indicadores por rango de fechas | D36: Could have | E36: CU-13 | F36: dashboard.js (desde, hasta) | G36: integration.test.js › dashboard KPI (rechaza rangos inválidos); borde de fecha | H36: Implementado y probado
A37: RF-33 | B37: Acceso móvil | C37: Cola ordenada por prioridad desde móvil, sin diferencias con escritorio | D37: Should have | E37: CU-09 | F37: ORDER BY prioridad, fecha_creacion en la API; PWA responsiva (viewport, 3 media queries) | G37: — | H37: Parcial | I37: Orden por prioridad implementado. Falta verificar en celulares reales y ampliar el diseño responsivo.
A38: RF-34 | B38: Acceso móvil | C38: Cambiar el estado de una incidencia desde móvil | D38: Should have | E38: CU-12 | F38: Misma interfaz que escritorio | G38: — | H38: Parcial | I38: Falta verificarlo en celulares reales.
A39: RF-35 | B39: Acceso móvil | C39: Almacenar y visualizar la evidencia fotográfica en el detalle | D39: Should have | E39: CU-05, CU-11 | F39: Tabla evidencias_fotograficas; sin carga ni visualización | G39: — | H39: Pendiente | I39: Depende de RF-12. Falta decidir almacenamiento (local o S3) y control de acceso.
A40: RF-36 | B40: Integración Casa Central | C40: Enviar (POST JSON) prioridad, ubicación y tipo de falla a Casa Central | D40: Sin clasificar | E40: CU-07 | F40: backend/src/integrations/casaCentralClient.js (mock) | G40: integrations.test.js › CasaCentralClient mock | H40: Mock | I40: No existe el POST real. El contrato técnico (autenticación, payload, sandbox) está pendiente con TI de Mallplaza.
A41: RF-37 | B41: Integración Casa Central | C41: Recibir y guardar el id de Orden de Trabajo devuelto por Casa Central | D41: Sin clasificar | E41: CU-07 | F41: Columna id_externo_mallplaza y restricción del esquema (ENVIADO exige id) | G41: migration.test.js (esquema) | H41: Parcial | I41: El almacenamiento existe; la recepción real depende de RF-36.
...

Sheet Matriz RNF
A1: Matriz de trazabilidad — Requerimientos no funcionales (14 RNF)
A2: RNF-02 y RNF-07 se verifican al desplegar en AWS con HTTPS; en el prototipo local figuran como 'Diseñado (no desplegado)', no como incumplidos.
A4: ID | B4: Categoría | C4: Requisito (resumen) | D4: Componente o evidencia | E4: Prueba automatizada | F4: Estado | G4: Observación o brecha
A5: RNF-01 | B5: Usabilidad | C5: Aplicación web responsiva (PWA), sin app nativa | D5: frontend/vite.config.js (manifest y service worker con vite-plugin-pwa) | E5: Build verificado (precache generado) | F5: Implementado | G5: Instalación y uso sin conexión no probados en dispositivos reales.
A6: RNF-02 | B6: Disponibilidad | C6: Operar en AWS con alta disponibilidad | D6: docs/procesos-y-arquitectura.md (infraestructura objetivo) | E6: — | F6: Diseñado (no desplegado) | G6: No hay VPC, Elastic Beanstalk ni RDS desplegados; el prototipo corre local con Docker.
A7: RNF-03 | B7: Usabilidad | C7: Identidad visual alineada con Mallplaza | D7: frontend/src/styles.css y manifest (color de tema rojo) | E7: — | F7: Parcial | G7: Estilo propio con color rojo aproximado; falta validar con la guía de marca.
A8: RNF-04 | B8: Rendimiento | C8: Formulario con respuesta ≤ 3 s en condiciones normales | D8: — | E8: — | F8: Pendiente | G8: Sin medición. Medir con pruebas de rendimiento en un entorno parecido a producción.
A9: RNF-05 | B9: Seguridad | C9: Cola y dashboard protegidos y restringidos a Jefatura | D9: middleware/auth.js; rutas protegidas | E9: integration.test.js › autenticación y dashboard KPI | F9: Implementado y probado
A10: RNF-06 | B10: Seguridad | C10: Contraseñas cifradas (bcrypt) | D10: backend/src/routes/auth.js; usuario semilla con bcrypt | E10: integration.test.js › autenticación | F10: Implementado y probado
A11: RNF-07 | B11: Seguridad | C11: Comunicación por HTTPS con TLS 1.2 o superior | D11: Diseño en docs; el entorno local usa HTTP | E11: — | F11: Diseñado (no desplegado) | G11: Se podrá verificar al desplegar con certificado. Además la cámara en PWA exige HTTPS.
A12: RNF-08 | B12: Datos | C12: Propiedades ACID en registro de incidencias y auditoría | D12: PostgreSQL; transacción BEGIN/COMMIT en el cambio de estado; restricciones y triggers en el esquema | E12: integration.test.js › incidencias; migration.test.js | F12: Implementado | G12: Cubierto por el motor y las pruebas de integración; sin prueba específica de atomicidad.
A13: RNF-09 | B13: Rendimiento | C13: Soportar el uso concurrente del personal operativo sin degradación | D13: Límites de tasa configurables (RATE_LIMIT_*) | E13: — | F13: Pendiente | G13: Falta definir el volumen esperado y hacer pruebas de carga.
A14: RNF-10 | B14: Cumplimiento | C14: Cumplir la Ley 21.719 en el tratamiento del RUT y otros datos | D14: RUT fuera de logs (logger con redacción) y fuera de la lista; solo visible en detalle autenticado | E14: logger.test.js; integration.test.js › protección de datos en logs | F14: Parcial | G14: Controles técnicos listos. Falta política de privacidad, base de licitud, retención y validación del responsable de datos de Mallplaza.
A15: RNF-11 | B15: Rendimiento | C15: Limitar tamaño y peso de imágenes adjuntas | D15: Solo restricciones parciales en el esquema | E15: — | F15: Pendiente | G15: Depende de RF-12.
A16: RNF-12 | B16: Calidad de datos | C16: Validar el RUT con módulo 11 | D16: backend/src/utils (validación de RUT) y filtros | E16: filters.test.js (RUT módulo 11) | F16: Implementado y probado
A17: RNF-13 | B17: Seguridad | C17: Credenciales de la API de Casa Central en variables de entorno | D17: backend/src/config.js carga secretos por entorno (JWT_SECRET, DATABASE_URL); .env no versionado | E17: config.test.js | F17: Parcial | G17: Aún no existen variables de Casa Central (el cliente es un mock).
A18: RNF-14 | B18: Interoperabilidad | C18: Los timeouts de Casa Central no deben bloquear la interfaz del operario | D18: El alta responde sin esperar a Casa Central y deja PENDIENTE_SINC | E18: — | F18: Parcial | G18: El diseño lo cumple, pero sin worker real no hay timeout que validar.

Sheet Casos de uso
A1: Casos de uso y requerimientos que cubren
A2: Las especificaciones detalladas están en el documento 'Especificación de casos de uso'. Todo RF del catálogo aparece en al menos un caso de uso (verificado en la columna de control).
A4: ID | B4: Caso de uso | C4: Actor principal | D4: RF y RNF relacionados | E4: Endpoint o componente | F4: Estado | G4: RF del catálogo sin caso de uso (control)
A5: CU-01 | B5: Iniciar sesión | C5: Jefatura | D5: RF-01, RF-02, RNF-05, RNF-06 | E5: POST /api/auth/login | F5: Implementado y probado | G5: =COUNTBLANK('Matriz RF'!E5:E44) -> 0
A6: CU-02 | B6: Cerrar sesión | C6: Jefatura | D6: RF-03 | E6: POST /api/auth/logout | F6: Implementado y probado | G6: (debe ser 0)
A7: CU-03 | B7: Acceder al formulario mediante QR | C7: Operario | D7: RF-04, RNF-01 | E7: Ruta /#/report; QR de demostración | F7: Parcial
A8: CU-04 | B8: Reportar incidencia | C8: Operario | D8: RF-05 a RF-11, RF-14, RF-15, RNF-12 | E8: POST /api/incidencias; GET /api/catalogos | F8: Implementado y probado
A9: CU-05 | B9: Adjuntar evidencia fotográfica | C9: Operario | D9: RF-12, RF-13, RF-35, RNF-11 | E9: Sin endpoint de carga | F9: Pendiente
A10: CU-06 | B10: Calcular prioridad | C10: Sistema (incluido en CU-04) | D10: RF-16, RF-17, RF-18 | E10: backend/src/rules/prioridad.js | F10: Implementado y probado
A11: CU-07 | B11: Sincronizar con Casa Central | C11: Sistema / Casa Central | D11: RF-36, RF-37, RF-38, RNF-07, RNF-13, RNF-14 | E11: casaCentralClient.js (mock); auditoriaApi.js | F11: Mock
A12: CU-08 | B12: Reintentar envío fallido | C12: Sistema | D12: RF-38, RF-39 | E12: Sin worker ni cola | F12: Pendiente
A13: CU-09 | B13: Consultar cola priorizada | C13: Jefatura | D13: RF-02, RF-33 | E13: GET /api/incidencias | F13: Implementado y probado
A14: CU-10 | B14: Filtrar y buscar incidencias | C14: Jefatura | D14: RF-23 a RF-27 | E14: GET /api/incidencias?estado=&prioridad=&ubicacion=&tipo_falla=&q= | F14: Implementado y probado
A15: CU-11 | B15: Consultar detalle e historial | C15: Jefatura | D15: RF-22, RF-35 | E15: GET /api/incidencias/:id | F15: Implementado y probado
A16: CU-12 | B16: Cambiar estado de una incidencia | C16: Jefatura | D16: RF-19, RF-20, RF-21, RF-34 | E16: PATCH /api/incidencias/:id/estado | F16: Implementado y probado
A17: CU-13 | B17: Consultar dashboard de KPI | C17: Jefatura | D17: RF-02, RF-28 a RF-32 | E17: GET /api/dashboard/kpis | F17: Implementado y probado
A18: CU-14 | B18: Visualizar estado de sincronización | C18: Jefatura | D18: RF-40 | E18: estado_sync en lista, detalle y dashboard | F18: Implementado

Sheet Pauta
A1: Cobertura de la pauta oficial (12 criterios)
A2: Revisión contra los documentos del repositorio y el Informe 1. 'Estado' mide qué tan cerca está de 'Excelente': Cubierto en texto = solo falta figura o ajuste; Parcial = falta contenido.
A4: Criterio | B4: Nombre | C4: Puntos máx. | D4: Dónde está hoy | E4: Brecha para 'Excelente' | F4: Acción sugerida | G4: Prioridad | H4: Estado
A5: 2.1.1.1 | B5: Análisis comparativo tecnológico y metodológico | C5: 6 | D5: docs/seleccion-tecnologias.md (comparación ponderada de tecnologías); Informe 1 §6.1 (Scrum frente a Cascada, plazo de 15 semanas, equipo de 3); costos en Informe 1 §6.4 y en el documento arquitectónico (CAPEX $3.506.000 CLP, 728 h-h, OPEX ≈ $42.500/mes). | E5: No aparece un estudio explícito de factibilidad técnica, económica e implementativa. La comparación de metodologías es cualitativa y solo contra Cascada; la pauta pide análisis cualitativo y cuantitativo. | F5: Agregar una tabla de metodologías (Scrum, Kanban, XP, Cascada) con criterios ponderados y un apartado de factibilidad en tres partes usando CAPEX/OPEX ya calculados. | G5: Media | H5: Parcial
A6: 2.1.1.2 | B6: Descripción de herramientas y componentes | C6: 4.8 | D6: docs/seleccion-tecnologias.md §5-6 y docs/ejecucion-local.md (stack, requisitos de notebook: 4 núcleos, 8 GB RAM). | E6: Falta un inventario consolidado de lenguajes, herramientas, hardware y servicios con versión y rol. El tipo de instancia AWS no está definido. | F6: Tabla única: software, hardware (equipos de desarrollo y servidor), servicios AWS y de terceros, con propuesta de dimensionamiento. | G6: Baja | H6: Parcial
A7: 2.1.2.3 | B7: Modelado BPMN (≥ 3 procesos con subprocesos) | C7: 6 | D7: Se entregan los 3 procesos en BPMN 2.0 (Reporte y priorización; Gestión y cierre; Sincronización con Casa Central) con 8 subprocesos, figuras PNG y archivos .bpmn editables, más su descripción. | E7: Falta revisión del profesor sobre la notación y, si se exige una herramienta específica, reexportar desde ella. | F7: Revisar y ajustar la disposición en bpmn.io o Camunda Modeler si se desea. | G7: Media | H7: Entregado
A8: 2.1.2.4 | B8: UML de casos de uso y de componentes | C8: 4.8 | D8: Se entregan el diagrama de casos de uso (14 CU) con su especificación completa. El diagrama de componentes del repositorio y el del Informe 1 siguen vigentes. | E8: Falta actualizar el diagrama de componentes con el worker de reintentos y el almacenamiento de evidencias. | F8: Actualizar el diagrama de componentes; insertar el de casos de uso en el informe. | G8: Media | H8: Parcial
A9: 2.1.2.5 | B9: Modelo y diccionario de datos | C9: 4.8 | D9: db/schema.sql; docs/datos-kpi-sla.md §1-2 (diagrama erDiagram en Mermaid y diccionario). | E9: El diagrama está en Mermaid y falta como figura exportada. Si se aprueba una tabla de zonas, hay que actualizar modelo y diccionario. | F9: Exportar el diagrama ER a imagen, revisar que el diccionario refleje cada columna y su restricción. | G9: Baja | H9: Cubierto en texto
A10: 2.1.2.6 | B10: Topología de comunicación | C10: 4.8 | D10: Figura A (topología de comunicación) con protocolos, puertos y zonas, para el entorno objetivo en AWS y el prototipo local; descrita en el documento 'Topología, infraestructura y arquitectura TI'. | E10: Decisiones abiertas: balanceador y DNS no presupuestados (D11) y definición del contrato con Casa Central. | F10: Resolver D11 y reflejarlo en la figura. | G10: Media | H10: Entregado
A11: 2.1.2.7 | B11: Diseño de infraestructura | C11: 3.6 | D11: Figura B (infraestructura en AWS) con VPC, zonas de disponibilidad, subredes, grupos de seguridad y servicios gestionados, distinguiendo lo presupuestado de lo opcional. | E11: La configuración presupuestada es de una zona y una instancia; la alta disponibilidad es opcional y con costo (D10). El presupuesto dice MySQL (D9). | F11: Corregir el presupuesto a PostgreSQL y decidir sobre Multi-AZ. | G11: Media | H11: Entregado
A12: 2.1.2.8 | B12: Diagrama de arquitectura TI | C12: 3.6 | D12: Figura C (arquitectura TI) con las tres capas de software y su correspondencia con el hardware y los servicios de infraestructura. | E12: Sin brechas de contenido; depende de las decisiones de infraestructura. | F12: Insertar las tres figuras en el informe con su descripción. | G12: Baja | H12: Entregado
A13: 2.1.3.9 | B13: KPIs SMART | C13: 6 | D13: Documento 'KPI SMART y niveles de servicio' con 10 indicadores y las cinco dimensiones SMART por indicador. | E13: Metas por validar con la Jefatura y volumen mensual estimado para la trazabilidad digital. | F13: Validar metas y línea base con la Jefatura. | G13: Media | H13: Entregado
A14: 2.1.3.10 | B14: Acuerdos de nivel de servicio (SLA) | C14: 4.8 | D14: Mismo documento: SLA operativo, SLA de plataforma (severidades S1 a S4) y niveles técnicos de servicio. | E14: El 99,9 % de disponibilidad no es coherente con el presupuesto de una zona (D10). | F14: Decidir el objetivo de disponibilidad. | G14: Media | H14: Entregado
A15: 2.1.4.11 | B15: Plan de pruebas de software | C15: 6 | D15: docs/calidad-operacion-plan.md §1 (tipos de prueba y estado); suite de 33 pruebas automatizadas; columna 'Prueba automatizada' de esta matriz. | E15: Se agregó la hoja 'Casos de prueba' con 46 casos ejecutados (45 aprobados y 1 hallazgo de seguridad) y 18 casos pendientes (10 manuales y 8 bloqueados por funcionalidad pendiente). Falta ejecutar los casos con celulares reales y UAT con el cliente, y guardar capturas de la ejecución como evidencia. | F15: Ejecutar los casos MAN (celular real y cliente), guardar capturas y, si se acuerda, resolver el hallazgo del token de sesión (TC-46). | G15: Media | H15: Parcial
A16: 2.1.4.12 | B16: Normas y estándares aplicados | C16: 4.8 | D16: docs/calidad-operacion-plan.md §2 (Ley 21.719, OWASP Top 10 y ASVS, ISO/IEC 27001/27002, ISO/IEC 25010, OWASP API Security); Informe 1 (Leyes 19.628, 21.663 y 21.719). | E16: Falta vincular cada norma con los RF/RNF donde se aplica. El documento arquitectónico menciona ISO 14001 y 45001 para la bitácora, pero no figuran en los documentos del repositorio. | F16: Tabla norma → motivo → requisito afectado → evidencia en el sistema. Decidir si se incluyen ISO 14001/45001 y bajo qué argumento. | G16: Media | H16: Cubierto en texto
B17: Total de puntos de la pauta | C17: =SUM(C5:C16) -> 60
B18: Puntos en criterios con prioridad Alta | C18: =SUMIF(G5:G16,"Alta",C5:C16) -> 0
B19: Puntos en criterios solo con ajuste de figura | C19: =SUMIF(H5:H16,"Cubierto en texto",C5:C16) -> 9.6
B20: Puntos con documento o figura ya entregado (por validar) | C20: =SUMIF(H5:H16,"Entregado",C5:C16) -> 28.8

Sheet Discrepancias
A1: Puntos a resolver (conflictos entre documentos)
A3: ID | B3: Tema | C3: Qué dicen los documentos | D3: Por qué importa | E3: Acción sugerida
A4: D1 | B4: Cantidad de requisitos | C4: El Informe 1 habla de 35 RF y 12 RNF con priorización MoSCoW. El catálogo actual tiene 40 RF y 14 RNF. | D4: RF-36 a RF-40 (integración con Casa Central) y RNF-13 y RNF-14 no están clasificados ni descritos en el Informe 1. | E4: Actualizar el capítulo de requisitos y la tabla MoSCoW del informe.
A5: D2 | B5: Quién usa el QR | C5: RF-04 dice 'acceso abierto, sin login'. El documento arquitectónico dice que el escaneo está 'restringido estrictamente al personal interno' con un QR provisto por la jefatura. El prototipo hoy deja la ruta pública. | D5: Son tres versiones distintas del mismo punto, y afecta seguridad y la defensa del RNF-10. | E5: Decidir con el cliente y dejar una sola redacción. Si el QR es de uso interno, definir cómo se protege (código por operario, acceso solo en la red del mall, etc.).
A6: D3 | B6: QR por sector frente a RF-05 | C6: El catálogo (RF-04 y RF-05) y el documento arquitectónico describen el QR como acceso al formulario, donde el operario elige la zona de una lista. La propuesta de 'QR por sector con ubicación precargada' no está en el catálogo. | D6: Esa propuesta cambia dos RF. Sin cambio formal, el prototipo ya cumple RF-04 y RF-05 en su forma actual. | E6: Mantener RF-04/05 tal como están. Si se quiere QR por sector, registrarlo como RF nuevo o como mejora futura. Aun así sirve la tabla de zonas: cada zona lleva su nivel de tránsito.
A7: D4 | B7: Zonas frente a niveles de tránsito | C7: El Informe 1 define la ubicación como tres categorías de tránsito y el prototipo la implementa así. RF-05 dice 'ubicación/zona', que podría leerse como zonas físicas del mall. | D7: Si el cliente espera zonas físicas, RF-05 quedaría parcial y habría que agregar una tabla de zonas, cada una con su nivel de tránsito (el árbol de decisión sigue necesitándolo). | E7: Preguntarle a Mauricio Maldonado cuál de las dos lecturas quiere. Mientras tanto, RF-05 se considera cumplido con la definición del Informe 1.
A8: D5 | B8: Fotos: opcional y mínimo 1 | C8: RF-12 dice que es opcional y que admite un mínimo de 1 y un máximo de 3. | D8: El requisito se contradice a sí mismo. | E8: Interpretar como 0 fotos o entre 1 y 3, y confirmarlo con el cliente.
A9: D6 | B9: RUT sin validación cruzada y módulo 11 | C9: RF-06 dice que no hay validación cruzada con bases corporativas; RNF-12 exige módulo 11. | D9: Son compatibles (formato frente a existencia), pero conviene decirlo expresamente. | E9: Aclarar en el informe: se valida formato, no existencia.
A10: D7 | B10: Fecha de cierre | C10: El documento arquitectónico fija el cierre y el prototipo operativo a principios de diciembre (con pruebas en sandbox y capacitación). Los documentos del repositorio hablan de entrega y exposición el 14-oct. | D10: El alcance del 14-oct debe presentarse como etapa intermedia, no como producto final. | E10: Confirmar qué se entrega el 14-oct y qué en diciembre; ajustar el plan y el discurso de la demo.
A11: D8 | B11: Requisitos de infraestructura en un prototipo local | C11: RNF-02 (AWS) y RNF-07 (HTTPS) se exigen, pero el prototipo corre local sobre HTTP. | D11: Pueden parecer incumplimientos. | E11: Presentarlos como 'diseñado, se verifica al desplegar' y explicar el plan de despliegue.
A12: D9 | B12: Base de datos en el presupuesto | C12: El presupuesto del Informe 1 contempla 'Amazon RDS para MySQL'; el sistema, el esquema y los demás documentos usan PostgreSQL. | D12: El costo y la tecnología del informe no coinciden con lo construido, y una cotización de AWS distinta puede cambiar los $42.500 CLP mensuales. | E12: Corregir el Informe 1 a PostgreSQL y cotizar RDS PostgreSQL db.t3.micro con la calculadora de AWS.
A13: D10 | B13: Disponibilidad frente a lo presupuestado | C13: El Informe 1 promete 99,9 % de disponibilidad, pero presupuesta una sola instancia EC2 t3.micro y RDS en una sola zona (Single-AZ). | D13: Esa configuración no respalda por diseño un 99,9 %: haría falta más de una instancia y la base en dos zonas, con costo adicional. | E13: Bajar el objetivo (por ejemplo al 99,5 % que plantea el repositorio) o presupuestar la alta disponibilidad.
A14: D11 | B14: Balanceador y DNS fuera del presupuesto | C14: Los documentos de arquitectura mencionan balanceador HTTPS y DNS con certificado, pero el presupuesto solo incluye RDS y Elastic Beanstalk. | D14: Sin balanceador, el certificado TLS debe configurarse en la propia instancia; con balanceador hay un costo mensual adicional. | E14: Decidir cuál de las dos opciones se adopta y reflejarla en la figura de infraestructura y en el presupuesto.
A15: D12 | B15: Dos presupuestos distintos | C15: El Informe 1 presupone $3.932.000 CLP (recursos humanos $3.600.000). El documento de definición arquitectónica del 6-oct habla de un CAPEX de $3.506.000 CLP con 728 horas-hombre. | D15: Una diferencia de $426.000 sin explicar resta credibilidad al análisis de factibilidad económica. | E15: Reconciliar ambos montos y usar una sola cifra en el informe final. La hoja 'Factibilidad económica' calcula con las dos.

Sheet Casos de prueba
A1: Casos de prueba y resultados de ejecución
A2: Los casos TC se ejecutaron el 10-oct-2026 contra el backend (Node 22, PostgreSQL 16) sobre una base limpia, por HTTP, con el script ejecutar-casos-api.js. Es un entorno de pruebas local, no producción. Los casos MAN requieren celular real o al cliente; los BLQ dependen de funcionalidad pendiente. Además de estos casos, la suite automatizada del repositorio (33 pruebas) pasó completa.
A4: ID | B4: Tipo | C4: RF / RNF | D4: Caso de uso | E4: Descripción | F4: Precondiciones | G4: Pasos | H4: Datos de entrada | I4: Resultado esperado | J4: Método | K4: Resultado obtenido | L4: Estado | M4: Fecha | N4: Observación
A5: TC-01 | B5: Funcional | C5: RF-01, RNF-06 | D5: CU-01 | E5: Inicio de sesión con credenciales válidas | F5: Usuario Jefatura activo | G5: POST /api/auth/login con correo y contraseña | H5: Credenciales de prueba | I5: HTTP 200 y cookie de sesión | J5: API (script de pruebas) | K5: HTTP 200 · cookie recibida | L5: Aprobado | M5: 10-oct-2026
A6: TC-02 | B6: Seguridad | C6: RF-01 | D6: CU-01 | E6: Contraseña incorrecta | F6: Usuario Jefatura activo | G6: POST /api/auth/login con contraseña errónea | H6: Contraseña incorrecta | I6: HTTP 401 con mensaje genérico | J6: API (script de pruebas) | K6: HTTP 401 · INVALID_CREDENTIALS · «Credenciales inválidas» | L6: Aprobado | M6: 10-oct-2026
A7: TC-03 | B7: Seguridad | C7: RF-01 | D7: CU-01 | E7: Correo inexistente: mensaje idéntico al de contraseña incorrecta | F7: — | G7: POST /api/auth/login con correo no registrado | H7: Correo inexistente | I7: HTTP 401 y el mismo mensaje que TC-02 | J7: API (script de pruebas) | K7: HTTP 401 · INVALID_CREDENTIALS · «Credenciales inválidas» | L7: Aprobado | M7: 10-oct-2026
A8: TC-04 | B8: Seguridad | C8: RF-02, RNF-05 | D8: CU-09 | E8: Cola sin sesión | F8: Sin cookie de sesión | G8: GET /api/incidencias sin cookie | H8: — | I8: HTTP 401 | J8: API (script de pruebas) | K8: HTTP 401 · UNAUTHORIZED | L8: Aprobado | M8: 10-oct-2026
A9: TC-05 | B9: Seguridad | C9: RF-02, RNF-05 | D9: CU-13 | E9: Dashboard sin sesión | F9: Sin cookie de sesión | G9: GET /api/dashboard/kpis sin cookie | H9: — | I9: HTTP 401 | J9: API (script de pruebas) | K9: HTTP 401 · UNAUTHORIZED | L9: Aprobado | M9: 10-oct-2026
A10: TC-06 | B10: Funcional | C10: RF-03 | D10: CU-02 | E10: Cierre de sesión | F10: Sesión activa | G10: POST /api/auth/logout | H10: — | I10: HTTP 204 (sin contenido) y cookie invalidada | J10: API (script de pruebas) | K10: HTTP 204 · cookie invalidada | L10: Aprobado | M10: 10-oct-2026 | N10: Expectativa corregida: la API responde 204, no 200.
A11: TC-07 | B11: Funcional | C11: RF-04 a RF-11, RF-14, RF-15, RF-18 | D11: CU-04 | E11: Alta válida de incidencia | F11: Servidor activo; sin sesión | G11: POST /api/incidencias con todos los campos | H11: RUT 11111111-1, alto tránsito, impacto operativo Sí, comentario | I11: HTTP 201 con número, prioridad y estado Pendiente | J11: API (script de pruebas) | K11: HTTP 201 · id 1 · prioridad CRITICA · estado PENDIENTE | L11: Aprobado | M11: 10-oct-2026
A12: TC-08 | B12: Validación | C12: RF-06, RF-14 | D12: CU-04 | E12: Alta sin RUT | F12: — | G12: POST /api/incidencias sin rut_operario | H12: RUT ausente | I12: HTTP 400 por validación | J12: API (script de pruebas) | K12: HTTP 400 · VALIDATION_ERROR | L12: Aprobado | M12: 10-oct-2026
A13: TC-09 | B13: Validación | C13: RNF-12 | D13: CU-04 | E13: RUT con dígito verificador inválido (módulo 11) | F13: — | G13: POST /api/incidencias con RUT 11111111-2 | H13: RUT con dígito verificador incorrecto | I13: HTTP 400 por validación | J13: API (script de pruebas) | K13: HTTP 400 · VALIDATION_ERROR | L13: Aprobado | M13: 10-oct-2026
A14: TC-10 | B14: Validación | C14: RF-08, RF-14 | D14: CU-04 | E14: Alta sin el campo obligatorio de impacto operativo | F14: — | G14: POST /api/incidencias sin impacto_operativo | H14: Campo ausente | I14: HTTP 400 por validación | J14: API (script de pruebas) | K14: HTTP 400 · VALIDATION_ERROR | L14: Aprobado | M14: 10-oct-2026
A15: TC-11 | B15: Validación | C15: RF-07 | D15: CU-04 | E15: Tipo de falla fuera del catálogo | F15: — | G15: POST /api/incidencias con tipo_falla inexistente | H15: tipo_falla = PLOMERIA_X | I15: HTTP 400 por validación | J15: API (script de pruebas) | K15: HTTP 400 · VALIDATION_ERROR | L15: Aprobado | M15: 10-oct-2026
A16: TC-12 | B16: Validación | C16: RF-05 | D16: CU-04 | E16: Ubicación fuera del catálogo | F16: — | G16: POST /api/incidencias con ubicación inexistente | H16: ubicacion = SECTOR_X | I16: HTTP 400 por validación | J16: API (script de pruebas) | K16: HTTP 400 · VALIDATION_ERROR | L16: Aprobado | M16: 10-oct-2026
A17: TC-13 | B17: Funcional | C17: RF-11 | D17: CU-04 | E17: Alta sin comentario (campo opcional) | F17: — | G17: POST /api/incidencias sin comentario | H17: Sin comentario | I17: HTTP 201 | J17: API (script de pruebas) | K17: HTTP 201 · prioridad BAJA | L17: Aprobado | M17: 10-oct-2026
A18: TC-14 | B18: Seguridad | C18: RNF-10 | D18: CU-04 | E18: La respuesta del alta no devuelve el RUT | F18: Alta realizada en TC-07 | G18: Revisar el cuerpo de la respuesta del alta | H18: — | I18: El cuerpo no contiene el RUT | J18: API (script de pruebas) | K18: El cuerpo no contiene el RUT | L18: Aprobado | M18: 10-oct-2026
A19: TC-15 | B19: Funcional | C19: RF-16, RF-17 | D19: CU-06 | E19: Prioridad: Alto tránsito + impacto operativo | F19: — | G19: POST /api/incidencias y leer la prioridad devuelta | H19: Alto tránsito + impacto operativo | I19: Prioridad CRITICA | J19: API (script de pruebas) | K19: HTTP 201 · prioridad CRITICA | L19: Aprobado | M19: 10-oct-2026
A20: TC-16 | B20: Funcional | C20: RF-16, RF-17 | D20: CU-06 | E20: Prioridad: Bajo tránsito + riesgo de accidente | F20: — | G20: POST /api/incidencias y leer la prioridad devuelta | H20: Bajo tránsito + riesgo de accidente | I20: Prioridad ALTA | J20: API (script de pruebas) | K20: HTTP 201 · prioridad ALTA | L20: Aprobado | M20: 10-oct-2026
A21: TC-17 | B21: Funcional | C21: RF-16, RF-17 | D21: CU-06 | E21: Prioridad: Bajo tránsito + afecta a terceros | F21: — | G21: POST /api/incidencias y leer la prioridad devuelta | H21: Bajo tránsito + afecta a terceros | I21: Prioridad ALTA | J21: API (script de pruebas) | K21: HTTP 201 · prioridad ALTA | L21: Aprobado | M21: 10-oct-2026
A22: TC-18 | B22: Funcional | C22: RF-16, RF-17 | D22: CU-06 | E22: Prioridad: Alto tránsito sin otros factores | F22: — | G22: POST /api/incidencias y leer la prioridad devuelta | H22: Alto tránsito sin otros factores | I22: Prioridad MEDIA | J22: API (script de pruebas) | K22: HTTP 201 · prioridad MEDIA | L22: Aprobado | M22: 10-oct-2026
... A47: TC-43 | B47: Operación | C47: — | D47: — | E47: Verificación de salud sin consultar la base | F47: — | G47: GET /health | H47: — | I47: HTTP 200 | J47: API (script de pruebas) | K47: HTTP 200 | L47: Aprobado | M47: 10-oct-2026
A48: TC-44 | B48: Rendimiento | C48: RNF-04 | D48: CU-04 | E48: Tiempo de respuesta del alta (30 envíos seguidos, entorno local) | F48: Base limpia, sin carga | G48: 30 POST secuenciales a /api/incidencias | H48: Reporte válido | I48: p95 menor a 3 000 ms (referencia local, no es producción) | J48: API (script de pruebas) | K48: p50 3 ms · p95 6 ms · máx 6 ms | L48: Aprobado | M48: 10-oct-2026 | N48: Medición local sin red móvil; no reemplaza la prueba en un entorno parecido a producción.
A49: TC-45 | B49: Rendimiento | C49: RNF-09, RNF-08 | D49: CU-04 | E49: 20 envíos simultáneos sin pérdidas ni duplicados (entorno local) | F49: Base limpia | G49: 20 POST en paralelo | H49: Reporte válido | I49: 20 respuestas 201 con identificadores distintos | J49: API (script de pruebas) | K49: 20 con HTTP 201 · 20 identificadores distintos · máx 143 ms | L49: Aprobado | M49: 10-oct-2026 | N49: Prueba ligera de concurrencia; no equivale a una prueba de carga con el volumen real.
A50: TC-46 | B50: Seguridad | C50: RF-03, RNF-05 | D50: CU-02 | E50: Reutilizar la cookie anterior después de cerrar sesión | F50: Cierre de sesión hecho (TC-06) | G50: GET /api/auth/me con la cookie previa al cierre | H50: Cookie copiada antes del cierre | I50: HTTP 401 | J50: API (script de pruebas) | K50: HTTP 200 | L50: Observación | M50: 10-oct-2026 | N50: HALLAZGO: la cookie copiada antes del cierre sigue siendo válida hasta que expira (vigencia de 8 h; el token no se revoca en el servidor). RF-03 cumple en el navegador, pero conviene acortar la vigencia o agregar revocación.
A51: MAN-01 | B51: Aceptación | C51: RF-04 | D51: CU-03 | E51: Escanear el QR con un iPhone y abrir el formulario | F51: App accesible desde el celular (misma red o HTTPS); QR impreso o en pantalla | G51: Abrir la cámara nativa, apuntar al QR, abrir el enlace | H51: QR de demostración | I51: Se abre /#/report y el formulario carga con sus listas | J51: Manual | L51: Por ejecutar | N51: Requiere dispositivo real o participación del cliente.
A52: MAN-02 | B52: Aceptación | C52: RF-04 | D52: CU-03 | E52: Escanear el QR con un Android | F52: Igual que MAN-01 | G52: Escanear con la cámara o con Google Lens | H52: QR de demostración | I52: Se abre el formulario | J52: Manual | L52: Por ejecutar | N52: Requiere dispositivo real o participación del cliente.
A53: MAN-03 | B53: Usabilidad | C53: RNF-01 | D53: CU-03 | E53: Instalar la PWA en la pantalla de inicio y abrirla | F53: Navegador móvil compatible; HTTPS o localhost | G53: Usar «Agregar a pantalla de inicio» y abrir el ícono | H53: — | I53: Abre en modo independiente con el nombre e ícono definidos | J53: Manual | L53: Por ejecutar | N53: Requiere dispositivo real o participación del cliente.
A54: MAN-04 | B54: Usabilidad | C54: RNF-01, RNF-14 | D54: CU-03 | E54: Comportamiento sin conexión | F54: PWA instalada y abierta una vez | G54: Activar modo avión, abrir la app e intentar enviar | H54: — | I54: La interfaz carga; el envío falla con un mensaje claro y no se pierde nada | J54: Manual | L54: Por ejecutar | N54: Requiere dispositivo real o participación del cliente.
A55: MAN-05 | B55: Aceptación | C55: RF-33, RF-34 | D55: CU-09, CU-12 | E55: Cola y cambio de estado desde un celular | F55: Sesión de Jefatura en un celular real (ancho cercano a 375 px) | G55: Ver la cola, filtrar, abrir un detalle y pasar a En proceso | H55: Incidencia de prueba | I55: Mismas funciones que en escritorio; sin textos cortados ni controles inalcanzables | J55: Manual | L55: Por ejecutar | N55: Requiere dispositivo real o participación del cliente.
A56: MAN-06 | B56: Funcional | C56: RF-03 | D56: CU-02 | E56: Cierre de sesión sin errores de red visibles | F56: Navegador con herramientas de desarrollo abiertas (tarea T6) | G56: Cerrar sesión y revisar la pestaña de red | H56: — | I56: Una solicitud de cierre completada; sin ERR_ABORTED | J56: Manual | L56: Por ejecutar | N56: Requiere dispositivo real o participación del cliente.
A57: MAN-07 | B57: Usabilidad | C57: RNF-03 | D57: — | E57: Revisión visual con la guía de marca de Mallplaza | F57: Guía de marca entregada por el cliente | G57: Comparar colores, tipografía y logotipo | H57: — | I57: Observaciones del cliente registradas | J57: Manual | L57: Por ejecutar | N57: Requiere dispositivo real o participación del cliente.
A58: MAN-08 | B58: Rendimiento | C58: RNF-04 | D58: CU-04 | E58: Tiempo de carga y envío del formulario en red móvil 4G | F58: Celular con 4G; servidor cercano a producción | G58: Medir carga inicial y envío con la herramienta de rendimiento del navegador | H58: Reporte válido | I58: Envío completado en 3 s o menos | J58: Manual | L58: Por ejecutar | N58: Requiere dispositivo real o participación del cliente.
A59: MAN-09 | B59: Usabilidad | C59: RNF-01, RF-14 | D59: CU-04 | E59: Prueba con 2 o 3 operarios reales | F59: Operarios sin entrenamiento previo | G59: Pedirles reportar una falla simulada y cronometrar | H59: Escenario ficticio | I59: Completan el reporte sin ayuda; se anotan dudas y tiempo | J59: Manual | L59: Por ejecutar | N59: Requiere dispositivo real o participación del cliente.
A60: MAN-10 | B60: Aceptación | C60: Varios | D60: CU-01 a CU-14 | E60: Aceptación (UAT) con la Jefatura de Mantenimiento | F60: Prototipo desplegado en el entorno acordado | G60: Recorrer el flujo completo con datos ficticios | H60: Escenario de demo | I60: Jefatura confirma o detalla cambios por escrito | J60: Manual | L60: Por ejecutar | N60: Requiere dispositivo real o participación del cliente.
A61: BLQ-01 | B61: Funcional | C61: RF-12, RF-13 | D61: CU-05 | E61: Adjuntar de 1 a 3 fotos y rechazar la cuarta | F61: Construir la carga de fotos | G61: Adjuntar tres imágenes y luego intentar una cuarta | H61: Imágenes de prueba | I61: Tres fotos aceptadas; la cuarta es rechazada | J61: Manual | L61: Bloqueado (funcionalidad pendiente) | N61: Depende de funcionalidad aún no construida.
A62: BLQ-02 | B62: Seguridad | C62: RNF-11 | D62: CU-05 | E62: Rechazar imágenes demasiado pesadas o de formato no permitido | F62: Construir la carga de fotos | G62: Subir una imagen sobre el límite y un archivo no imagen | H62: Archivos de prueba | I62: Ambos rechazados con mensaje claro | J62: Manual | L62: Bloqueado (funcionalidad pendiente) | N62: Depende de funcionalidad aún no construida.
... A68: BLQ-08 | B68: Disponibilidad | C68: RNF-02 | D68: — | E68: Disponibilidad ante la caída de una instancia | F68: Despliegue en AWS con alta disponibilidad | G68: Detener una instancia y medir la recuperación | H68: — | I68: El servicio sigue respondiendo o se recupera en el tiempo acordado | J68: Manual | L68: Bloqueado (funcionalidad pendiente) | N68: Depende de funcionalidad aún no construida.

Sheet Metodologías
A1: Análisis comparativo de metodologías de desarrollo
A2: Puntajes de 1 (débil) a 5 (muy favorable) propuestos para este proyecto, con su fundamento. Las celdas amarillas (pesos y puntajes) se pueden editar y los resultados se recalculan. Son una evaluación del equipo, no una medición: conviene ajustarlos con su experiencia real y validar con el profesor guía.
A4: Criterio | B4: Peso (%) | C4: Scrum | D4: Kanban | E4: XP | F4: Cascada | G4: Fundamento de los puntajes
A5: Adaptación a requisitos cambiantes o pendientes de validación | B5: 25 | C5: 5 | D5: 4 | E5: 5 | F5: 1 | G5: Los RF son una propuesta sujeta a revisión del cliente y el contrato con Casa Central sigue abierto. Scrum y XP absorben cambios por iteración; Kanban también, sin hitos; Cascada exige congelar requisitos al inicio.
A6: Entregas incrementales verificables dentro de 15 semanas | B6: 20 | C6: 5 | D6: 3 | E6: 4 | F6: 2 | G6: Scrum entrega software funcional en cada sprint de 2 a 3 semanas. Kanban no fija plazos de iteración. Cascada entrega recién al final.
A7: Adecuación a un equipo pequeño (3 integrantes) | B7: 15 | C7: 4 | D7: 5 | E7: 3 | F7: 3 | G7: Kanban casi no exige ceremonias. Scrum funciona con equipos pequeños. XP exige programación en pares y prácticas técnicas intensas.
A8: Trazabilidad y evidencia documental para la evaluación académica | B8: 15 | C8: 4 | D8: 3 | E8: 2 | F8: 5 | G8: Cascada produce documentación completa. Scrum deja evidencia en backlog, sprints y revisiones. XP documenta poco por diseño.
A9: Gestión temprana de riesgos e incertidumbre técnica (integración) | B9: 10 | C9: 5 | D9: 3 | E9: 4 | F9: 1 | G9: Scrum permite validar la integración con Casa Central en sprints tempranos. Cascada la deja para el final.
A10: Participación frecuente del sponsor y del cliente | B10: 10 | C10: 5 | D10: 3 | E10: 5 | F10: 2 | G10: Scrum prevé revisiones de sprint con el sponsor; XP pide cliente presente. En Cascada el cliente reaparece al final.
A11: Curva de aprendizaje y costo de adopción | B11: 5 | C11: 4 | D11: 5 | E11: 2 | F11: 5 | G11: Kanban y Cascada son simples de adoptar. XP exige disciplina técnica (pruebas primero, pares) que el equipo no practica hoy.
A12: Suma de pesos (debe ser 100) | B12: =SUM(B5:B11) -> 100
A13: Resultado ponderado (0 a 100) | C13: =SUMPRODUCT($B$5:$B$11,C5:C11)/SUM($B$5:$B$11)*20 -> 93 | D13: =SUMPRODUCT($B$5:$B$11,D5:D11)/SUM($B$5:$B$11)*20 -> 73 | E13: =SUMPRODUCT($B$5:$B$11,E5:E11)/SUM($B$5:$B$11)*20 -> 76 | F13: =SUMPRODUCT($B$5:$B$11,F5:F11)/SUM($B$5:$B$11)*20 -> 48
A14: Posición | C14: =RANK(C13,$C$13:$F$13) -> 1 | D14: =RANK(D13,$C$13:$F$13) -> 3 | E14: =RANK(E13,$C$13:$F$13) -> 2 | F14: =RANK(F13,$C$13:$F$13) -> 4
A15: Metodología con mayor puntaje | C15: =INDEX($C$4:$F$4,MATCH(MAX($C$13:$F$13),$C$13:$F$13,0)) -> Scrum
A17: Análisis de sensibilidad (¿cambia el resultado si se mueven los pesos?)
A18: Escenario | C18: Scrum | D18: Kanban | E18: XP | F18: Cascada | G18: Lectura
A19: A. Sin el criterio de trazabilidad documental (el que más favorece a Cascada) | C19: =(SUMPRODUCT($B$5:$B$11,C5:C11)-$B$8*C8)/(SUM($B$5:$B$11)-$B$8)*20 -> 95.294118 | D19: =(SUMPRODUCT($B$5:$B$11,D5:D11)-$B$8*D8)/(SUM($B$5:$B$11)-$B$8)*20 -> 75.294118 | E19: =(SUMPRODUCT($B$5:$B$11,E5:E11)-$B$8*E8)/(SUM($B$5:$B$11)-$B$8)*20 -> 82.352941 | F19: =(SUMPRODUCT($B$5:$B$11,F5:F11)-$B$8*F8)/(SUM($B$5:$B$11)-$B$8)*20 -> 38.823529 | G19: ="Mayor puntaje: "&INDEX($C$18:$F$18,MATCH(MAX(C19:F19),C19:F19,0)) -> Mayor puntaje: Scrum
A20: B. Todos los criterios con el mismo peso | C20: =AVERAGE(C5:C11)*20 -> 91.428571 | D20: =AVERAGE(D5:D11)*20 -> 74.285714 | E20: =AVERAGE(E5:E11)*20 -> 71.428571 | F20: =AVERAGE(F5:F11)*20 -> 54.285714 | G20: ="Mayor puntaje: "&INDEX($C$18:$F$18,MATCH(MAX(C20:F20),C20:F20,0)) -> Mayor puntaje: Scrum
A21: C. Sin el criterio de equipo pequeño (el que más favorece a Kanban) | C21: =(SUMPRODUCT($B$5:$B$11,C5:C11)-$B$7*C7)/(SUM($B$5:$B$11)-$B$7)*20 -> 95.294118 | D21: =(SUMPRODUCT($B$5:$B$11,D5:D11)-$B$7*D7)/(SUM($B$5:$B$11)-$B$7)*20 -> 68.235294 | E21: =(SUMPRODUCT($B$5:$B$11,E5:E11)-$B$7*E7)/(SUM($B$5:$B$11)-$B$7)*20 -> 78.823529 | F21: =(SUMPRODUCT($B$5:$B$11,F5:F11)-$B$7*F7)/(SUM($B$5:$B$11)-$B$7)*20 -> 45.882353 | G21: ="Mayor puntaje: "&INDEX($C$18:$F$18,MATCH(MAX(C21:F21),C21:F21,0)) -> Mayor puntaje: Scrum

Sheet Tecnologías
A1: Análisis comparativo de tecnologías (backend y base de datos)
A2: Pesos y puntajes tomados de docs/seleccion-tecnologias.md (de 1 a 5). Se agrega un análisis de sensibilidad: el criterio de 'ajuste al stack definido' favorece a la tecnología ya elegida, así que se recalcula sin él para comprobar que la conclusión no depende solo de eso.
A4: Backend: criterio | B4: Peso (%) | C4: Node.js + Express | D4: Python + Django REST | E4: Java + Spring Boot
A5: Ajuste a equipo y stack definido | B5: 25 | C5: 5 | D5: 2 | E5: 2
A6: Velocidad para API y MVP | B6: 20 | C6: 5 | D6: 4 | E6: 3
A7: Ecosistema y mantenimiento | B7: 15 | C7: 4 | D7: 4 | E7: 5
A8: Integración con PWA y JSON | B8: 15 | C8: 5 | D8: 4 | E8: 4
A9: Control explícito del diseño | B9: 10 | C9: 4 | D9: 3 | E9: 3
A10: Facilidad de despliegue en AWS | B10: 10 | C10: 4 | D10: 4 | E10: 4
A11: Curva y costo de operación inicial | B11: 5 | C11: 4 | D11: 4 | E11: 2
A12: Suma de pesos (debe ser 100) | B12: =SUM(B5:B11) -> 100
A13: Resultado ponderado (0 a 100) | C13: =SUMPRODUCT($B$5:$B$11,C5:C11)/SUM($B$5:$B$11)*20 -> 92 | D13: =SUMPRODUCT($B$5:$B$11,D5:D11)/SUM($B$5:$B$11)*20 -> 68 | E13: =SUMPRODUCT($B$5:$B$11,E5:E11)/SUM($B$5:$B$11)*20 -> 65
A14: Sin el criterio 'ajuste a equipo y stack' (renormalizado) | C14: =(SUMPRODUCT($B$5:$B$11,C5:C11)-$B$5*C5)/(SUM($B$5:$B$11)-$B$5)*20 -> 89.333333 | D14: =(SUMPRODUCT($B$5:$B$11,D5:D11)-$B$5*D5)/(SUM($B$5:$B$11)-$B$5)*20 -> 77.333333 | E14: =(SUMPRODUCT($B$5:$B$11,E5:E11)-$B$5*E5)/(SUM($B$5:$B$11)-$B$5)*20 -> 73.333333
A15: Mayor puntaje (sin el criterio de ajuste) | C15: =INDEX($C$4:$E$4,MATCH(MAX(C14:E14),C14:E14,0)) -> Node.js + Express
A18: Base de datos: criterio | B18: Peso (%) | C18: PostgreSQL | D18: MySQL | E18: MongoDB
A19: Integridad relacional, claves foráneas, CHECK y triggers | B19: 30 | C19: 5 | D19: 4 | E19: 2
A20: Consultas SQL y agregaciones para KPI | B20: 25 | C20: 5 | D20: 4 | E20: 3
A21: Tipos y restricciones útiles al dominio | B21: 15 | C21: 5 | D21: 4 | E21: 3
A22: Operación administrada en AWS | B22: 15 | C22: 5 | D22: 5 | E22: 4
A23: Ajuste al esquema aprobado | B23: 15 | C23: 5 | D23: 3 | E23: 2
A24: Suma de pesos (debe ser 100) | B24: =SUM(B19:B23) -> 100
A25: Resultado ponderado (0 a 100) | C25: =SUMPRODUCT($B$19:$B$23,C19:C23)/SUM($B$19:$B$23)*20 -> 100 | D25: =SUMPRODUCT($B$19:$B$23,D19:D23)/SUM($B$19:$B$23)*20 -> 80 | E25: =SUMPRODUCT($B$19:$B$23,E19:E23)/SUM($B$19:$B$23)*20 -> 54
A26: Sin el criterio 'ajuste al esquema aprobado' (renormalizado) | C26: =(SUMPRODUCT($B$19:$B$23,C19:C23)-$B$23*C23)/(SUM($B$19:$B$23)-$B$23)*20 -> 100 | D26: =(SUMPRODUCT($B$19:$B$23,D19:D23)-$B$23*D23)/(SUM($B$19:$B$23)-$B$23)*20 -> 83.529412 | E26: =(SUMPRODUCT($B$19:$B$23,E19:E23)-$B$23*E23)/(SUM($B$19:$B$23)-$B$23)*20 -> 56.470588
A27: Mayor puntaje (sin el criterio de ajuste) | C27: =INDEX($C$18:$E$18,MATCH(MAX(C26:E26),C26:E26,0)) -> PostgreSQL

Sheet Factibilidad económica
A1: Factibilidad económica: inversión, costo operativo y recuperación
A2: Cifras de entrada tomadas del Informe 1 y del documento de definición arquitectónica (celdas amarillas, editables). El ahorro bruto es el desperdicio de coordinación que estima el Informe 1; el 'porcentaje de captura' es la parte de ese ahorro que el sistema logra realmente, que es el supuesto más incierto.
A4: Concepto | B4: Valor | C4: Unidad | D4: Fuente
A5: Incidencias coordinadas por informalidad al día | B5: 15 | C5: incidencias | D5: Informe 1, diagnóstico
A6: Minutos perdidos por incidencia | B6: 15 | C6: minutos | D6: Informe 1, diagnóstico
A7: Días laborales al mes | B7: 20 | C7: días | D7: Informe 1, diagnóstico
A8: Costo de la hora-hombre operativa | B8: 5000 | C8: CLP | D8: Informe 1, diagnóstico
A9: Horas-hombre perdidas al mes | B9: =B5*B6*B7/60 -> 75 | C9: horas | D9: Cálculo
A10: Ahorro bruto mensual si el sistema elimina todo el desperdicio | B10: =B9*B8 -> 375000 | C10: CLP al mes | D10: Cálculo (el Informe 1 informa $375.000)
A11: Costo operativo mensual de la nube (RDS + Elastic Beanstalk) | B11: 42500 | C11: CLP al mes | D11: Informe 1, ≈ USD 45 a $935
A12: Inversión inicial, presupuesto del Informe 1 | B12: =SUM(B20:B26) -> 3932000 | C12: CLP | D12: Suma del desglose (tabla de abajo)
A13: Inversión inicial (CAPEX), documento de definición arquitectónica | B13: 3506000 | C13: CLP | D13: 728 horas-hombre y AWS por 15 semanas
A14: Diferencia entre ambos presupuestos | B14: =B12-B13 -> 426000 | C14: CLP | D14: Hay que reconciliarlos
A17: Desglose del presupuesto del Informe 1 | B17: Monto (CLP)
A20: Licencias de aplicaciones | B20: 0
A21: Servicios profesionales | B21: 0
A22: Hardware y software básico | B22: 80000
A23: Recursos humanos | B23: 3600000
A24: Capacitación | B24: 72000
A25: Gastos de viaje (visitas a terreno) | B25: 30000
A26: Infraestructura AWS (15 semanas) | B26: 150000
A27: Total | B27: =SUM(B20:B26) -> 3932000
A30: Escenario de captura del ahorro | B30: Ahorro neto mensual (CLP) | C30: Recuperación con el presupuesto del Informe 1 (meses) | D30: Recuperación con el CAPEX del documento arquitectónico (meses) | E30: Acumulado neto a 5 años, presupuesto del Informe 1 (CLP)
A31: 1 | B31: =$B$10*A31-$B$11 -> 332500 | C31: =IF(B31>0,$B$12/B31,"No se recupera") -> 11.825564 | D31: =IF(B31>0,$B$13/B31,"No se recupera") -> 10.544361 | E31: =B31*60-$B$12 -> 16018000
A32: 0.75 | B32: =$B$10*A32-$B$11 -> 238750 | C32: =IF(B32>0,$B$12/B32,"No se recupera") -> 16.46911 | D32: =IF(B32>0,$B$13/B32,"No se recupera") -> 14.684817 | E32: =B32*60-$B$12 -> 10393000
A33: 0.5 | B33: =$B$10*A33-$B$11 -> 145000 | C33: =IF(B33>0,$B$12/B33,"No se recupera") -> 27.117241 | D33: =IF(B33>0,$B$13/B33,"No se recupera") -> 24.17931 | E33: =B33*60-$B$12 -> 4768000
A34: 0.25 | B34: =$B$10*A34-$B$11 -> 51250 | C34: =IF(B34>0,$B$12/B34,"No se recupera") -> 76.721951 | D34: =IF(B34>0,$B$13/B34,"No se recupera") -> 68.409756 | E34: =B34*60-$B$12 -> -857000
A36: Captura mínima para recuperar la inversión en 5 años (presupuesto del Informe 1) | B36: =($B$12/60+$B$11)/$B$10 -> 0.28808889
A37: Captura mínima para recuperar la inversión en 3 años (presupuesto del Informe 1) | B37: =($B$12/36+$B$11)/$B$10 -> 0.40459259
A39: Nota: el 'costo' de recursos humanos valora las horas de los estudiantes bajo el modelo de fábrica de software; no es un desembolso de Mallplaza. El costo real para el cliente depende del precio comercial que se acuerde. Las 75 horas mensuales son una estimación del Informe 1, no una medición.
